<?xml version="1.0" ?>
<!-- =================================================================================== -->
<!-- |    This document was autogenerated by xacro from finder.xacro                   | -->
<!-- |    EDITING THIS FILE BY HAND IS NOT RECOMMENDED                                 | -->
<!-- =================================================================================== -->
<!--Taller de Robotica Abierta
	FinDER robot xacro file 
	developed by Cesar Pineda 
	December 2016 - January 2017
NOTA: NO utilizar acentos en codigo ni en comentarios, de lo contrario no se podra convertir a URDF.-->
<!-- Rojo= X, Verde=Y y Azul= Z (color de los ejes en Rviz)-->
<robot name="finder" xmlns:xacro="http://www.ros.org/wiki/xacro">
  <!-- Macro para "mandar llamar" a las mallas *.obj -->
  <!--General porpuse variables-->
  <!--Inertial matrix macro-->
  <!--Macro para crear los eslabones y "mandar llamar" a los brazos laterales del chasis-->
  <!--Macro para crear las juntas de los brazos laterales con el chasis-->
  <!--parameters for geometries in collision tags-->
  <!--///////////////////// shoulder collision geometry//////////////////////////////-->
  <!--///////////////////// elbow  collision geometry//////////////////////////////-->
  <!--altura en y-->
  <!--altura en x-->
  <!--altura en z-->
  <!--///////////////////// elbow  collision geometry//////////////////////////////-->
  <!--altura en y-->
  <!--altura en x-->
  <!--altura en z-->
  <!--Cylinder parameters-->
  <!-- Grasping frame -->
  <material name="White">
    <color rgba="1.0 1.0 1.0 1.0"/>
  </material>
  <!--//////////////////////////  base link //////////////////-->
  <!--link name = "base_link"></link-->
  <link name="base_link">
    <visual>
      <geometry>
        <!-- Typically, STL/DAE/OBJ model units are in mm, but RViz units are in m, hence models must be scaled down by 1000-->
        <mesh filename="package://finder_description/mallas/chasis.obj" scale="0.001 0.001 0.001"/>
      </geometry>
      <origin xyz="0 0 0"/>
    </visual>
    <collision>
      <geometry>
        <!-- Typically, STL/DAE/OBJ model units are in mm, but RViz units are in m, hence models must be scaled down by 1000-->
        <mesh filename="package://finder_description/mallas/chasis.obj" scale="0.001 0.001 0.001"/>
      </geometry>
      <origin xyz="0 0 0"/>
    </collision>
  </link>
  <!--////////////////// juntas de los brazos laterales del chasis //////////////////-->
  <!-- junta del brazo frontal derecho -->
  <joint name="right_front_flipper" type="revolute">
    <parent link="base_link"/>
    <child link="right_front_arm"/>
    <origin xyz="-0.3264 -0.30255 0.1556"/>
    <axis xyz="1 0 0"/>
    <limit effort="300" lower="-3.14159265359" upper="3.14159265359" velocity="0.1"/>
  </joint>
  <!-- junta del brazo frontal izquierdo -->
  <joint name="left_front_flipper" type="revolute">
    <parent link="base_link"/>
    <child link="left_front_arm"/>
    <origin xyz="0.3264 -0.30255 0.1556"/>
    <axis xyz="1 0 0"/>
    <limit effort="300" lower="-3.14159265359" upper="3.14159265359" velocity="0.1"/>
  </joint>
  <!-- junta del brazo trasero derecho -->
  <joint name="right_back_flipper" type="revolute">
    <parent link="base_link"/>
    <child link="right_back_arm"/>
    <origin xyz="-0.3264 0.30255 0.1556"/>
    <axis xyz="1 0 0"/>
    <limit effort="300" lower="-3.14159265359" upper="3.14159265359" velocity="0.1"/>
  </joint>
  <!-- junta del brazo trasero izquierdo -->
  <joint name="left_back_flipper" type="revolute">
    <parent link="base_link"/>
    <child link="left_back_arm"/>
    <origin xyz="0.3264 0.30255 0.1556"/>
    <axis xyz="1 0 0"/>
    <limit effort="300" lower="-3.14159265359" upper="3.14159265359" velocity="0.1"/>
  </joint>
  <!--////////////// brazos laterales del chasis ////////////////////-->
  <!-- brazo frontal derecho chasis -->
  <link name="right_front_arm">
    <visual>
      <geometry>
        <!-- Typically, STL/DAE/OBJ model units are in mm, but RViz units are in m, hence models must be scaled down by 1000-->
        <mesh filename="package://finder_description/mallas/brazo_der_frontal.obj" scale="0.001 0.001 0.001"/>
      </geometry>
      <origin xyz="0.3264 0.30255 -0.0629"/>
    </visual>
    <collision>
      <geometry>
        <!-- Typically, STL/DAE/OBJ model units are in mm, but RViz units are in m, hence models must be scaled down by 1000-->
        <mesh filename="package://finder_description/mallas/brazo_der_frontal.obj" scale="0.001 0.001 0.001"/>
      </geometry>
      <origin xyz="0.3264 0.30255 -0.0629"/>
    </collision>
  </link>
  <!-- brazo frontal izquierdo chasis -->
  <link name="left_front_arm">
    <visual>
      <geometry>
        <!-- Typically, STL/DAE/OBJ model units are in mm, but RViz units are in m, hence models must be scaled down by 1000-->
        <mesh filename="package://finder_description/mallas/brazo_izq_frontal.obj" scale="0.001 0.001 0.001"/>
      </geometry>
      <origin xyz="-0.3264 0.30255 -0.0629"/>
    </visual>
    <collision>
      <geometry>
        <!-- Typically, STL/DAE/OBJ model units are in mm, but RViz units are in m, hence models must be scaled down by 1000-->
        <mesh filename="package://finder_description/mallas/brazo_izq_frontal.obj" scale="0.001 0.001 0.001"/>
      </geometry>
      <origin xyz="-0.3264 0.30255 -0.0629"/>
    </collision>
  </link>
  <!-- brazo trasero derecho chasis -->
  <link name="right_back_arm">
    <visual>
      <geometry>
        <!-- Typically, STL/DAE/OBJ model units are in mm, but RViz units are in m, hence models must be scaled down by 1000-->
        <mesh filename="package://finder_description/mallas/brazo_der_trasero.obj" scale="0.001 0.001 0.001"/>
      </geometry>
      <origin xyz="0.3264 -0.30255 -0.0629"/>
    </visual>
    <collision>
      <geometry>
        <!-- Typically, STL/DAE/OBJ model units are in mm, but RViz units are in m, hence models must be scaled down by 1000-->
        <mesh filename="package://finder_description/mallas/brazo_der_trasero.obj" scale="0.001 0.001 0.001"/>
      </geometry>
      <origin xyz="0.3264 -0.30255 -0.0629"/>
    </collision>
  </link>
  <!-- brazo trasero izquierdo chasis -->
  <link name="left_back_arm">
    <visual>
      <geometry>
        <!-- Typically, STL/DAE/OBJ model units are in mm, but RViz units are in m, hence models must be scaled down by 1000-->
        <mesh filename="package://finder_description/mallas/brazo_izq_trasero.obj" scale="0.001 0.001 0.001"/>
      </geometry>
      <origin xyz="-0.3264 -0.30255 -0.0629"/>
    </visual>
    <collision>
      <geometry>
        <!-- Typically, STL/DAE/OBJ model units are in mm, but RViz units are in m, hence models must be scaled down by 1000-->
        <mesh filename="package://finder_description/mallas/brazo_izq_trasero.obj" scale="0.001 0.001 0.001"/>
      </geometry>
      <origin xyz="-0.3264 -0.30255 -0.0629"/>
    </collision>
  </link>
  <!--///////////////// Brazo 6GDL + Gripper//////////////////-->
  <!--////////////////// "eje tronco" rotation joint //////////////////-->
  <joint name="base_rotation" type="revolute">
    <parent link="base_link"/>
    <child link="eje_tronco"/>
    <origin rpy="0 0 0" xyz="0 -0.30645 0.2236"/>
    <axis xyz="0 0 1"/>
    <limit effort="300" lower="-3.14159265359" upper="3.14159265359" velocity="0.1"/>
  </joint>
  <!--////////////////// "eje tronco link" //////////////////-->
  <link name="eje_tronco">
    <visual>
      <geometry>
        <!-- Typically, STL/DAE/OBJ model units are in mm, but RViz units are in m, hence models must be scaled down by 1000-->
        <mesh filename="package://finder_description/mallas/base.obj" scale="0.001 0.001 0.001"/>
      </geometry>
      <origin xyz="0 0 0"/>
    </visual>
    <collision>
      <geometry>
        <!-- Typically, STL/DAE/OBJ model units are in mm, but RViz units are in m, hence models must be scaled down by 1000-->
        <mesh filename="package://finder_description/mallas/base.obj" scale="0.001 0.001 0.001"/>
      </geometry>
    </collision>
  </link>
  <!--//////////////////"eje_tronco-shoulder rotation joint//////////////////-->
  <joint name="shoulder_rotation" type="revolute">
    <parent link="eje_tronco"/>
    <child link="shoulder"/>
    <origin xyz="0 -0.0035 0.179"/>
    <axis xyz="1 0 0"/>
    <!--limit effort="300" velocity="0.1" lower="${-pi}" upper="${pi}"/-->
    <limit effort="300" lower="0" upper="3.1" velocity="0.1"/>
  </joint>
  <!--////////////////////// shoulder link //////////////////////-->
  <link name="shoulder">
    <visual>
      <geometry>
        <!-- Typically, STL/DAE/OBJ model units are in mm, but RViz units are in m, hence models must be scaled down by 1000-->
        <mesh filename="package://finder_description/mallas/hombro.obj" scale="0.001 0.001 0.001"/>
      </geometry>
      <origin xyz="0 0.0035 -0.0338"/>
    </visual>
    <collision>
      <origin xyz="0 0.0035 -0.0338"/>
      <geometry>
        <!-- Typically, STL/DAE/OBJ model units are in mm, but RViz units are in m, hence models must be scaled down by 1000-->
        <mesh filename="package://finder_description/mallas/hombro.obj" scale="0.001 0.001 0.001"/>
      </geometry>
    </collision>
  </link>
  <!--///////////////////// "shoulder-elbow" rotation joint ////////////////////////////-->
  <joint name="elbow_rotation" type="revolute">
    <parent link="shoulder"/>
    <child link="elbow"/>
    <origin xyz="0 0.423 0.0363"/>
    <axis xyz="1 0 0"/>
    <!--limit effort="300" velocity="0.1" lower="${-pi}" upper="${pi}"/-->
    <limit effort="300" lower="-2.3" upper="0" velocity="0.1"/>
  </joint>
  <!--////////////////////// elbow link /////////////////////////////////////-->
  <link name="elbow">
    <visual>
      <!--origin xyz= "0 -0.4192 -0.027"/-->
      <origin xyz="0 -0.668 -0.027"/>
      <geometry>
        <!-- Typically, STL/DAE/OBJ model units are in mm, but RViz units are in m, hence models must be scaled down by 1000-->
        <mesh filename="package://finder_description/mallas/codo.obj" scale="0.001 0.001 0.001"/>
      </geometry>
    </visual>
    <collision>
      <origin xyz="0 -0.4192 -0.027"/>
      <geometry>
        <!-- Typically, STL/DAE/OBJ model units are in mm, but RViz units are in m, hence models must be scaled down by 1000-->
        <mesh filename="package://finder_description/mallas/codo.obj" scale="0.001 0.001 0.001"/>
      </geometry>
    </collision>
  </link>
  <!--/////////////////////// roll joint ///////////////////////-->
  <joint name="roll_rotation" type="revolute">
    <parent link="elbow"/>
    <child link="roll"/>
    <origin xyz="0 -0.4192 0.0103"/>
    <axis xyz="0 1 0"/>
    <limit effort="300" lower="-3.14159265359" upper="3.14159265359" velocity="0.1"/>
  </joint>
  <!--//////////////////// roll link ////////////////////////////////-->
  <link name="roll">
    <visual>
      <geometry>
        <!-- Typically, STL/DAE/OBJ model units are in mm, but RViz units are in m, hence models must be scaled down by 1000-->
        <mesh filename="package://finder_description/mallas/roll1.obj" scale="0.001 0.001 0.001"/>
      </geometry>
      <origin xyz="0 0 -0.0188"/>
    </visual>
    <collision>
      <origin rpy="0 0 0" xyz="0 0 -0.0188"/>
      <geometry>
        <!-- Typically, STL/DAE/OBJ model units are in mm, but RViz units are in m, hence models must be scaled down by 1000-->
        <mesh filename="package://finder_description/mallas/roll1.obj" scale="0.001 0.001 0.001"/>
      </geometry>
    </collision>
  </link>
  <!--///////////////// pitch rotation joint////////////////////////////////-->
  <joint name="pitch_rotation" type="revolute">
    <parent link="roll"/>
    <child link="pitch"/>
    <origin xyz="0 -0.0778 0"/>
    <axis xyz="1 0 0"/>
    <!--limit effort="300" velocity="0.1" lower="${-pi}" upper="${pi}"/-->
    <limit effort="300" lower="-1.0471975512" upper="1.0471975512" velocity="0.1"/>
  </joint>
  <!--//////////////////// pitch link ////////////////////////7-->
  <link name="pitch">
    <visual>
      <geometry>
        <!-- Typically, STL/DAE/OBJ model units are in mm, but RViz units are in m, hence models must be scaled down by 1000-->
        <mesh filename="package://finder_description/mallas/pitch_light.obj" scale="0.001 0.001 0.001"/>
      </geometry>
      <!--origin xyz= "0 0.0778 -0.0188"/-->
      <origin xyz="0 0.048 -0.0188"/>
    </visual>
    <collision>
      <geometry>
        <!-- Typically, STL/DAE/OBJ model units are in mm, but RViz units are in m, hence models must be scaled down by 1000-->
        <mesh filename="package://finder_description/mallas/pitch_light.obj" scale="0.001 0.001 0.001"/>
      </geometry>
      <origin xyz="0 0.0778 -0.0188"/>
    </collision>
  </link>
  <!--////////////////////// yaw rotation joint /////////////////////////////7-->
  <joint name="roll_rotation_2" type="revolute">
    <parent link="pitch"/>
    <child link="yaw"/>
    <origin xyz="0 -0.0835 0"/>
    <axis xyz="0 1 0"/>
    <limit effort="300" lower="-3.14159265359" upper="3.14159265359" velocity="0.1"/>
  </joint>
  <!-- ///////////////////// yaw link ///////////////////////////////-->
  <link name="yaw">
    <visual>
      <geometry>
        <!-- Typically, STL/DAE/OBJ model units are in mm, but RViz units are in m, hence models must be scaled down by 1000-->
        <mesh filename="package://finder_description/mallas/yaw.obj" scale="0.001 0.001 0.001"/>
      </geometry>
      <!--origin xyz= "0.0007 0 0.00053"/-->
      <origin xyz="0.0007 0 -0.019"/>
    </visual>
    <collision>
      <geometry>
        <!-- Typically, STL/DAE/OBJ model units are in mm, but RViz units are in m, hence models must be scaled down by 1000-->
        <mesh filename="package://finder_description/mallas/yaw.obj" scale="0.001 0.001 0.001"/>
      </geometry>
      <!--origin xyz= "0.0007 0 0.00053"/-->
      <origin xyz="0.0007 0 -0.019"/>
    </collision>
  </link>
  <!--////////////////////// gripper rotation joint /////////////////////////////7-->
  <joint name="gripper_rotation" type="revolute">
    <parent link="yaw"/>
    <child link="gripper"/>
    <origin xyz="-0.0147485 -0.003042 0"/>
    <axis xyz="0 0 1"/>
    <!--limit effort="300" velocity="0.1" lower="${-pi}" upper="${pi}"/-->
    <limit effort="300" lower="0" upper="3.14159265359" velocity="0.1"/>
  </joint>
  <!-- ///////////////////// gripper link ///////////////////////////////-->
  <link name="gripper">
    <visual>
      <geometry>
        <!-- Typically, STL/DAE/OBJ model units are in mm, but RViz units are in m, hence models must be scaled down by 1000-->
        <mesh filename="package://finder_description/mallas/fingers.obj" scale="0.001 0.001 0.001"/>
      </geometry>
      <origin xyz="-0.00425 0.0071 -0.035"/>
    </visual>
    <collision>
      <geometry>
        <!-- Typically, STL/DAE/OBJ model units are in mm, but RViz units are in m, hence models must be scaled down by 1000-->
        <mesh filename="package://finder_description/mallas/fingers.obj" scale="0.001 0.001 0.001"/>
      </geometry>
      <origin xyz="-0.00425 0.0071 0"/>
    </collision>
  </link>
  <link name="grasping_frame">
    <inertial>
      <origin rpy="0 0 0" xyz="0 0 0"/>
      <mass value="0.001"/>
      <cuboid_inertia mass="0.0001" x="0.001" y="0.001" z="0.001"/>
      <inertia ixx="1.0" ixy="0.0" ixz="0.0" iyy="100.0" iyz="0.0" izz="1.0"/>
    </inertial>
    <visual>
      <origin xyz="0 0 0"/>
      <geometry>
        <box size="0.02 0.02 0.02"/>
      </geometry>
      <material name="White"/>
    </visual>
  </link>
  <!-- ////////////// Finger-Grasping joint///////////// -->
  <joint name="grasping_frame_joint" type="fixed">
    <parent link="yaw"/>
    <child link="grasping_frame"/>
    <origin xyz="-0.023 -0.1 0"/>
  </joint>
</robot>

